Traceback (most recent call last):
  File "/base/python_lib/versions/1/google/appengine/ext/webapp/__init__.py", line 499, in __call__
    handler.get(*groups)
  File "/base/data/home/apps/slushr/1.329741463437421940/slushd.py", line 264, in get
    points = Point.all().order('-date_created').fetch(200,start)
  File "/base/python_lib/versions/1/google/appengine/ext/db/__init__.py", line 1377, in fetch
    raw = self._get_query().Get(limit, offset)
  File "/base/python_lib/versions/1/google/appengine/api/datastore.py", line 938, in Get
    return self._Run(limit, offset)._Next(limit)
  File "/base/python_lib/versions/1/google/appengine/api/datastore.py", line 882, in _Run
    _ToDatastoreError(err)
  File "/base/python_lib/versions/1/google/appengine/api/datastore.py", line 1636, in _ToDatastoreError
    raise errors[err.application_error](err.error_detail)
BadRequestError: offset may not be above 4000
